Workbook

Sheet Anleitung
A1: uaEFI moto – Signal- und Pinbelegung
A3: So bearbeitest du die Belegung:
A4: 1. Im Blatt "Signale" nur die gelben Spalten ändern: Stecker (A, B, EGT oder leer), Pin, Kabelfarbe, Querschnitt.
A5: 2. Die Blätter "Stecker A", "Stecker B" und "EGT" zeigen automatisch, was auf jedem Pin liegt, inkl. freier und doppelt belegter Pins.
A6: 3. Das Blatt "Prüfung" zeigt je Gruppe, ob die Regeln eingehalten sind (rot = Problem).
A7: 4. Neue Signale: einfach unten im Blatt "Signale" eine Zeile anhängen (bis Zeile 150 wird alles ausgewertet).
A8: 5. Zum Verkabeln die Blätter "Stecker A", "Stecker B" und "EGT" ausdrucken: Pin, Signal, Kabelfarbe, Querschnitt in Pin-Reihenfolge.
A10: Regeln:
A11: • Eine Gruppe (z. B. Lambda 1, alle Einspritzdüsen, VR) liegt komplett auf einem Stecker.
A12: • Versorgung 12V, 5V Sensorversorgung und Sensormasse müssen auf beiden Steckern A und B vorkommen.
A13: • Masse (Leistungsmasse, USB-Masse, VR-Schirm) darf auf beiden liegen.
A14: • Jeder Pin höchstens einmal. Stecker A und B haben je 34 Pins, der EGT-Block 8 (4 Buchsen × 2).
... A29: • Einspritzung/Zündung 5–6 sind auf der Platine vorhanden, aber nicht auf den Steckern.

Sheet Signale
A1: Gruppe | B1: Signal | C1: Netz (Schaltplan) | D1: MCU / rusEFI | E1: Typ | F1: Strom max | G1: Stecker | H1: Pin | I1: Bemerkung | J1: Schlüssel | K1: Status | L1: Kabelfarbe | M1: Querschnitt mm²
A2: Versorgung 12V | B2: +12V Batterie / ECU-Versorgung | C2: +12V | D2: - | E2: Versorgung | F2: 2 A | G2: A | H2: 1 | I2: über F2 auf +12V_RAW | J2: =IF(OR(G2="",H2=""),"",G2&"-"&H2) | K2: =IF(A2="","",IF(J2="","nicht belegt",IF(COUNTIF($J$2:$J$150,J2)>1,"DOPPELT",IF(OR(H2<1,H2>IF(G2="EGT",8,34)),"Pin ungültig","ok")))) | M2: 0.75
A3: Versorgung 12V | B3: Zündung (Schlüssel) | C3: /12V_KEY | D3: MM100_IN_VBATT (PA5 über Teiler) | E3: Eingang | F3: 0,1 A | G3: A | H3: 2 | I3: ohne Main-Relais identisch mit +12V | J3: =IF(OR(G3="",H3=""),"",G3&"-"&H3) | K3: =IF(A3="","",IF(J3="","nicht belegt",IF(COUNTIF($J$2:$J$150,J3)>1,"DOPPELT",IF(OR(H3<1,H3>IF(G3="EGT",8,34)),"Pin ungültig","ok")))) | M3: 0.5
A4: Versorgung 12V | B4: +12V Hallsensoren (A) | C4: /12V_HALL | D4: - | E4: Versorgung | F4: 0,2 A | G4: A | H4: 3 | I4: PTC F11 200 mA, gleiches Netz wie B1 | J4: =IF(OR(G4="",H4=""),"",G4&"-"&H4) | K4: =IF(A4="","",IF(J4="","nicht belegt",IF(COUNTIF($J$2:$J$150,J4)>1,"DOPPELT",IF(OR(H4<1,H4>IF(G4="EGT",8,34)),"Pin ungültig","ok")))) | M4: 0.75
A5: 5V Sensorversorgung | B5: +5V Sensor (A1) | C5: +5VP | D5: - | E5: Versorgung | F5: 0,1 A | G5: A | H5: 4 | I5: geschützte 5V | J5: =IF(OR(G5="",H5=""),"",G5&"-"&H5) | K5: =IF(A5="","",IF(J5="","nicht belegt",IF(COUNTIF($J$2:$J$150,J5)>1,"DOPPELT",IF(OR(H5<1,H5>IF(G5="EGT",8,34)),"Pin ungültig","ok")))) | M5: 0.5
A6: 5V Sensorversorgung | B6: +5V Sensor (A2) | C6: +5VP | D6: - | E6: Versorgung | F6: 0,1 A | G6: A | H6: 5 | J6: =IF(OR(G6="",H6=""),"",G6&"-"&H6) | K6: =IF(A6="","",IF(J6="","nicht belegt",IF(COUNTIF($J$2:$J$150,J6)>1,"DOPPELT",IF(OR(H6<1,H6>IF(G6="EGT",8,34)),"Pin ungültig","ok")))) | M6: 0.5
A7: Sensormasse | B7: Sensormasse (A1) | C7: GNDA | D7: - | E7: Masse | F7: 0,1 A | G7: A | H7: 6 | J7: =IF(OR(G7="",H7=""),"",G7&"-"&H7) | K7: =IF(A7="","",IF(J7="","nicht belegt",IF(COUNTIF($J$2:$J$150,J7)>1,"DOPPELT",IF(OR(H7<1,H7>IF(G7="EGT",8,34)),"Pin ungültig","ok")))) | M7: 0.5
A8: Sensormasse | B8: Sensormasse (A2) | C8: GNDA | D8: - | E8: Masse | F8: 0,1 A | G8: A | H8: 7 | J8: =IF(OR(G8="",H8=""),"",G8&"-"&H8) | K8: =IF(A8="","",IF(J8="","nicht belegt",IF(COUNTIF($J$2:$J$150,J8)>1,"DOPPELT",IF(OR(H8<1,H8>IF(G8="EGT",8,34)),"Pin ungültig","ok")))) | M8: 0.5
A9: Masse | B9: Leistungsmasse (A1) | C9: GND | D9: - | E9: Masse | F9: 10 A | G9: A | H9: 8 | J9: =IF(OR(G9="",H9=""),"",G9&"-"&H9) | K9: =IF(A9="","",IF(J9="","nicht belegt",IF(COUNTIF($J$2:$J$150,J9)>1,"DOPPELT",IF(OR(H9<1,H9>IF(G9="EGT",8,34)),"Pin ungültig","ok")))) | M9: 0.75
A10: Masse | B10: Leistungsmasse (A2) | C10: GND | D10: - | E10: Masse | F10: 10 A | G10: A | H10: 9 | J10: =IF(OR(G10="",H10=""),"",G10&"-"&H10) | K10: =IF(A10="","",IF(J10="","nicht belegt",IF(COUNTIF($J$2:$J$150,J10)>1,"DOPPELT",IF(OR(H10<1,H10>IF(G10="EGT",8,34)),"Pin ungültig","ok")))) | M10: 0.75
A11: Masse | B11: Leistungsmasse (A3) | C11: GND | D11: - | E11: Masse | F11: 10 A | G11: A | H11: 10 | J11: =IF(OR(G11="",H11=""),"",G11&"-"&H11) | K11: =IF(A11="","",IF(J11="","nicht belegt",IF(COUNTIF($J$2:$J$150,J11)>1,"DOPPELT",IF(OR(H11<1,H11>IF(G11="EGT",8,34)),"Pin ungültig","ok")))) | M11: 0.75
A12: Einspritzung 1-2 | B12: Einspritzdüse 1 | C12: /OUT_INJ1 | D12: MM100_INJ1 (PD3) | E12: Low-Side | F12: 3 A | G12: A | H12: 11 | J12: =IF(OR(G12="",H12=""),"",G12&"-"&H12) | K12: =IF(A12="","",IF(J12="","nicht belegt",IF(COUNTIF($J$2:$J$150,J12)>1,"DOPPELT",IF(OR(H12<1,H12>IF(G12="EGT",8,34)),"Pin ungültig","ok")))) | M12: 0.75
A13: Einspritzung 1-2 | B13: Einspritzdüse 2 | C13: /OUT_INJ2 | D13: MM100_INJ2 (PA9) | E13: Low-Side | F13: 3 A | G13: A | H13: 12 | J13: =IF(OR(G13="",H13=""),"",G13&"-"&H13) | K13: =IF(A13="","",IF(J13="","nicht belegt",IF(COUNTIF($J$2:$J$150,J13)>1,"DOPPELT",IF(OR(H13<1,H13>IF(G13="EGT",8,34)),"Pin ungültig","ok")))) | M13: 0.75
A14: Einspritzung 3-4 | B14: Einspritzdüse 3 | C14: /OUT_INJ3 | D14: MM100_INJ3 (PD11) | E14: Low-Side | F14: 3 A | G14: B | H14: 5 | J14: =IF(OR(G14="",H14=""),"",G14&"-"&H14) | K14: =IF(A14="","",IF(J14="","nicht belegt",IF(COUNTIF($J$2:$J$150,J14)>1,"DOPPELT",IF(OR(H14<1,H14>IF(G14="EGT",8,34)),"Pin ungültig","ok")))) | M14: 0.75
A15: Einspritzung 3-4 | B15: Einspritzdüse 4 | C15: /OUT_INJ4 | D15: MM100_INJ4 (PD10) | E15: Low-Side | F15: 3 A | G15: B | H15: 6 | J15: =IF(OR(G15="",H15=""),"",G15&"-"&H15) | K15: =IF(A15="","",IF(J15="","nicht belegt",IF(COUNTIF($J$2:$J$150,J15)>1,"DOPPELT",IF(OR(H15<1,H15>IF(G15="EGT",8,34)),"Pin ungültig","ok")))) | M15: 0.75
A16: Einspritzung 5-6 (unbenutzt) | B16: Einspritzdüse 5 | C16: /OUT_INJ5 | D16: MM100_INJ5 (PD2) | E16: Low-Side | F16: 3 A | J16: =IF(OR(G16="",H16=""),"",G16&"-"&H16) | K16: =IF(A16="","",IF(J16="","nicht belegt",IF(COUNTIF($J$2:$J$150,J16)>1,"DOPPELT",IF(OR(H16<1,H16>IF(G16="EGT",8,34)),"Pin ungültig","ok"))))
A17: Einspritzung 5-6 (unbenutzt) | B17: Einspritzdüse 6 | C17: /OUT_INJ6 | D17: MM100_INJ6 (PA8) | E17: Low-Side | F17: 3 A | J17: =IF(OR(G17="",H17=""),"",G17&"-"&H17) | K17: =IF(A17="","",IF(J17="","nicht belegt",IF(COUNTIF($J$2:$J$150,J17)>1,"DOPPELT",IF(OR(H17<1,H17>IF(G17="EGT",8,34)),"Pin ungültig","ok"))))
A18: Zündung 1-2 | B18: Zündspule 1 | C18: /OUT_IGN1 | D18: MM100_IGN1 (PC13) | E18: Logik 5V | F18: 0,02 A | G18: A | H18: 13 | I18: für Spulen mit eingebauter Endstufe | J18: =IF(OR(G18="",H18=""),"",G18&"-"&H18) | K18: =IF(A18="","",IF(J18="","nicht belegt",IF(COUNTIF($J$2:$J$150,J18)>1,"DOPPELT",IF(OR(H18<1,H18>IF(G18="EGT",8,34)),"Pin ungültig","ok")))) | M18: 0.5
A19: Zündung 1-2 | B19: Zündspule 2 | C19: /OUT_IGN2 | D19: MM100_IGN2 (PE5) | E19: Logik 5V | F19: 0,02 A | G19: A | H19: 14 | I19: für Spulen mit eingebauter Endstufe | J19: =IF(OR(G19="",H19=""),"",G19&"-"&H19) | K19: =IF(A19="","",IF(J19="","nicht belegt",IF(COUNTIF($J$2:$J$150,J19)>1,"DOPPELT",IF(OR(H19<1,H19>IF(G19="EGT",8,34)),"Pin ungültig","ok")))) | M19: 0.5
A20: Zündung 3-4 | B20: Zündspule 3 | C20: /OUT_IGN3 | D20: MM100_IGN3 (PE4) | E20: Logik 5V | F20: 0,02 A | G20: B | H20: 7 | I20: für Spulen mit eingebauter Endstufe | J20: =IF(OR(G20="",H20=""),"",G20&"-"&H20) | K20: =IF(A20="","",IF(J20="","nicht belegt",IF(COUNTIF($J$2:$J$150,J20)>1,"DOPPELT",IF(OR(H20<1,H20>IF(G20="EGT",8,34)),"Pin ungültig","ok")))) | M20: 0.5
A21: Zündung 3-4 | B21: Zündspule 4 | C21: /OUT_IGN4 | D21: MM100_IGN4 (PE3) | E21: Logik 5V | F21: 0,02 A | G21: B | H21: 8 | I21: für Spulen mit eingebauter Endstufe | J21: =IF(OR(G21="",H21=""),"",G21&"-"&H21) | K21: =IF(A21="","",IF(J21="","nicht belegt",IF(COUNTIF($J$2:$J$150,J21)>1,"DOPPELT",IF(OR(H21<1,H21>IF(G21="EGT",8,34)),"Pin ungültig","ok")))) | M21: 0.5
A22: Zündung 5-6 (unbenutzt) | B22: Zündspule 5 | C22: /OUT_IGN5 | D22: MM100_IGN5 (PE2) | E22: Logik 5V | F22: 0,02 A | I22: für Spulen mit eingebauter Endstufe | J22: =IF(OR(G22="",H22=""),"",G22&"-"&H22) | K22: =IF(A22="","",IF(J22="","nicht belegt",IF(COUNTIF($J$2:$J$150,J22)>1,"DOPPELT",IF(OR(H22<1,H22>IF(G22="EGT",8,34)),"Pin ungültig","ok"))))
A23: Zündung 5-6 (unbenutzt) | B23: Zündspule 6 | C23: /OUT_IGN6 | D23: MM100_IGN6 (PB8) | E23: Logik 5V | F23: 0,02 A | I23: für Spulen mit eingebauter Endstufe | J23: =IF(OR(G23="",H23=""),"",G23&"-"&H23) | K23: =IF(A23="","",IF(J23="","nicht belegt",IF(COUNTIF($J$2:$J$150,J23)>1,"DOPPELT",IF(OR(H23<1,H23>IF(G23="EGT",8,34)),"Pin ungültig","ok"))))
A24: GPPWM 1-2 | B24: GPPWM1 | C24: /OUT_LS1 | D24: MM100_INJ7 (PD15) | E24: Low-Side | F24: 3 A | G24: A | H24: 15 | I24: mit Freilaufdiode | J24: =IF(OR(G24="",H24=""),"",G24&"-"&H24) | K24: =IF(A24="","",IF(J24="","nicht belegt",IF(COUNTIF($J$2:$J$150,J24)>1,"DOPPELT",IF(OR(H24<1,H24>IF(G24="EGT",8,34)),"Pin ungültig","ok")))) | M24: 0.75
A25: GPPWM 1-2 | B25: GPPWM2 | C25: /OUT_LS2 | D25: MM100_INJ8 (PD12) | E25: Low-Side | F25: 3 A | G25: A | H25: 16 | I25: mit Freilaufdiode | J25: =IF(OR(G25="",H25=""),"",G25&"-"&H25) | K25: =IF(A25="","",IF(J25="","nicht belegt",IF(COUNTIF($J$2:$J$150,J25)>1,"DOPPELT",IF(OR(H25<1,H25>IF(G25="EGT",8,34)),"Pin ungültig","ok")))) | M25: 0.75
A26: GPPWM 3-4 | B26: GPPWM3 | C26: /OUT_LS3 | D26: MM100_OUT_PWM1 (PD13) | E26: Low-Side | F26: 3 A | G26: B | H26: 9 | I26: mit Freilaufdiode | J26: =IF(OR(G26="",H26=""),"",G26&"-"&H26) | K26: =IF(A26="","",IF(J26="","nicht belegt",IF(COUNTIF($J$2:$J$150,J26)>1,"DOPPELT",IF(OR(H26<1,H26>IF(G26="EGT",8,34)),"Pin ungültig","ok")))) | M26: 0.75
A27: GPPWM 3-4 | B27: GPPWM4 | C27: /OUT_LS4 | D27: MM100_OUT_PWM2 (PC6) | E27: Low-Side | F27: 3 A | G27: B | H27: 10 | I27: mit Freilaufdiode | J27: =IF(OR(G27="",H27=""),"",G27&"-"&H27) | K27: =IF(A27="","",IF(J27="","nicht belegt",IF(COUNTIF($J$2:$J$150,J27)>1,"DOPPELT",IF(OR(H27<1,H27>IF(G27="EGT",8,34)),"Pin ungültig","ok")))) | M27: 0.75
A28: Basis-Sensoren | B28: TPS1 | C28: /IN_TPS1 | D28: MM100_IN_TPS (PA4) | E28: Analog 0–5V | F28: - | G28: A | H28: 17 | J28: =IF(OR(G28="",H28=""),"",G28&"-"&H28) | K28: =IF(A28="","",IF(J28="","nicht belegt",IF(COUNTIF($J$2:$J$150,J28)>1,"DOPPELT",IF(OR(H28<1,H28>IF(G28="EGT",8,34)),"Pin ungültig","ok")))) | M28: 0.5
A29: Basis-Sensoren | B29: CLT | C29: /IN_CLT | D29: MM100_IN_CLT (PC2) | E29: Analog 0–5V | F29: - | G29: A | H29: 18 | J29: =IF(OR(G29="",H29=""),"",G29&"-"&H29) | K29: =IF(A29="","",IF(J29="","nicht belegt",IF(COUNTIF($J$2:$J$150,J29)>1,"DOPPELT",IF(OR(H29<1,H29>IF(G29="EGT",8,34)),"Pin ungültig","ok")))) | M29: 0.5
A30: Basis-Sensoren | B30: IAT | C30: /IN_IAT | D30: MM100_IN_IAT (PC3) | E30: Analog 0–5V | F30: - | G30: A | H30: 19 | J30: =IF(OR(G30="",H30=""),"",G30&"-"&H30) | K30: =IF(A30="","",IF(J30="","nicht belegt",IF(COUNTIF($J$2:$J$150,J30)>1,"DOPPELT",IF(OR(H30<1,H30>IF(G30="EGT",8,34)),"Pin ungültig","ok")))) | M30: 0.5
A31: Hall 1 | B31: Hall 1 (Kurbelwelle) | C31: /IN_HALL1 | D31: MM100_IN_D1 (PE12) | E31: Digital | F31: - | G31: A | H31: 20 | I31: 4,7k Pull-up, Trigger in Firmware | J31: =IF(OR(G31="",H31=""),"",G31&"-"&H31) | K31: =IF(A31="","",IF(J31="","nicht belegt",IF(COUNTIF($J$2:$J$150,J31)>1,"DOPPELT",IF(OR(H31<1,H31>IF(G31="EGT",8,34)),"Pin ungültig","ok")))) | M31: 0.5
A32: Lambda 1 | B32: Lambda 1 Heizung + (LSU Pin 4) | C32: +12V_RAW | D32: Modul M5 | E32: Lambda | F32: 2 A | G32: A | H32: 21 | I32: kalt kurz bis 2 A | J32: =IF(OR(G32="",H32=""),"",G32&"-"&H32) | K32: =IF(A32="","",IF(J32="","nicht belegt",IF(COUNTIF($J$2:$J$150,J32)>1,"DOPPELT",IF(OR(H32<1,H32>IF(G32="EGT",8,34)),"Pin ungültig","ok")))) | M32: 0.75
A33: Lambda 1 | B33: Lambda 1 Heizung − (LSU Pin 3) | C33: /3_WBO_Heater | D33: Modul M5 | E33: Lambda | F33: 2 A | G33: A | H33: 22 | I33: kalt kurz bis 2 A | J33: =IF(OR(G33="",H33=""),"",G33&"-"&H33) | K33: =IF(A33="","",IF(J33="","nicht belegt",IF(COUNTIF($J$2:$J$150,J33)>1,"DOPPELT",IF(OR(H33<1,H33>IF(G33="EGT",8,34)),"Pin ungültig","ok")))) | M33: 0.75
A34: Lambda 1 | B34: Lambda 1 Ip (LSU Pin 1) | C34: /1_WBO_Ip | D34: Modul M5 | E34: Lambda | F34: 0,01 A | G34: A | H34: 23 | J34: =IF(OR(G34="",H34=""),"",G34&"-"&H34) | K34: =IF(A34="","",IF(J34="","nicht belegt",IF(COUNTIF($J$2:$J$150,J34)>1,"DOPPELT",IF(OR(H34<1,H34>IF(G34="EGT",8,34)),"Pin ungültig","ok")))) | M34: 0.5
A35: Lambda 1 | B35: Lambda 1 Vm (LSU Pin 2) | C35: /2_WBO_Vm | D35: Modul M5 | E35: Lambda | F35: 0,01 A | G35: A | H35: 24 | J35: =IF(OR(G35="",H35=""),"",G35&"-"&H35) | K35: =IF(A35="","",IF(J35="","nicht belegt",IF(COUNTIF($J$2:$J$150,J35)>1,"DOPPELT",IF(OR(H35<1,H35>IF(G35="EGT",8,34)),"Pin ungültig","ok")))) | M35: 0.5
A36: Lambda 1 | B36: Lambda 1 Un (LSU Pin 6) | C36: /6_WBO_Un | D36: Modul M5 | E36: Lambda | F36: 0,01 A | G36: A | H36: 25 | J36: =IF(OR(G36="",H36=""),"",G36&"-"&H36) | K36: =IF(A36="","",IF(J36="","nicht belegt",IF(COUNTIF($J$2:$J$150,J36)>1,"DOPPELT",IF(OR(H36<1,H36>IF(G36="EGT",8,34)),"Pin ungültig","ok")))) | M36: 0.5
A37: Lambda 1 | B37: Lambda 1 Rtrim (LSU Pin 5) | C37: /5_WBO_Rtrim | D37: Modul M5 | E37: Lambda | F37: 0,01 A | G37: A | H37: 26 | J37: =IF(OR(G37="",H37=""),"",G37&"-"&H37) | K37: =IF(A37="","",IF(J37="","nicht belegt",IF(COUNTIF($J$2:$J$150,J37)>1,"DOPPELT",IF(OR(H37<1,H37>IF(G37="EGT",8,34)),"Pin ungültig","ok")))) | M37: 0.5
A38: Lambda 2 | B38: Lambda 2 Heizung + (LSU Pin 4) | C38: +12V_RAW | D38: Modul M8 | E38: Lambda | F38: 2 A | G38: B | H38: 29 | I38: kalt kurz bis 2 A | J38: =IF(OR(G38="",H38=""),"",G38&"-"&H38) | K38: =IF(A38="","",IF(J38="","nicht belegt",IF(COUNTIF($J$2:$J$150,J38)>1,"DOPPELT",IF(OR(H38<1,H38>IF(G38="EGT",8,34)),"Pin ungültig","ok")))) | M38: 0.75
A39: Lambda 2 | B39: Lambda 2 Heizung − (LSU Pin 3) | C39: /WBO2_Heater | D39: Modul M8 | E39: Lambda | F39: 2 A | G39: B | H39: 30 | I39: kalt kurz bis 2 A | J39: =IF(OR(G39="",H39=""),"",G39&"-"&H39) | K39: =IF(A39="","",IF(J39="","nicht belegt",IF(COUNTIF($J$2:$J$150,J39)>1,"DOPPELT",IF(OR(H39<1,H39>IF(G39="EGT",8,34)),"Pin ungültig","ok")))) | M39: 0.75
A40: Lambda 2 | B40: Lambda 2 Ip (LSU Pin 1) | C40: /WBO2_Ip | D40: Modul M8 | E40: Lambda | F40: 0,01 A | G40: B | H40: 31 | J40: =IF(OR(G40="",H40=""),"",G40&"-"&H40) | K40: =IF(A40="","",IF(J40="","nicht belegt",IF(COUNTIF($J$2:$J$150,J40)>1,"DOPPELT",IF(OR(H40<1,H40>IF(G40="EGT",8,34)),"Pin ungültig","ok")))) | M40: 0.5
...

Sheet Prüfung
A1: Gruppe | B1: Regel | C1: Signale | D1: auf A | E1: auf B | F1: auf EGT | G1: nicht belegt | H1: Ergebnis
A2: Versorgung 12V | B2: auf A und B | C2: =COUNTIF(Signale!$A$2:$A$150,A2) | D2: =COUNTIFS(Signale!$A$2:$A$150,A2,Signale!$G$2:$G$150,"A") | E2: =COUNTIFS(Signale!$A$2:$A$150,A2,Signale!$G$2:$G$150,"B") | F2: =COUNTIFS(Signale!$A$2:$A$150,A2,Signale!$G$2:$G$150,"EGT") | G2: =C2-D2-E2-F2 | H2: =IF(B2="auf A und B",IF(AND(D2>0,E2>0),"ok","FEHLT auf "&IF(D2=0,"A","B")),IF(B2="ein Stecker",IF((D2>0)+(E2>0)+(F2>0)>1,"GETEILT",IF(G2>0,"teilweise unbelegt","ok")),"ok"))
A3: 5V Sensorversorgung | B3: auf A und B | C3: =COUNTIF(Signale!$A$2:$A$150,A3) | D3: =COUNTIFS(Signale!$A$2:$A$150,A3,Signale!$G$2:$G$150,"A") | E3: =COUNTIFS(Signale!$A$2:$A$150,A3,Signale!$G$2:$G$150,"B") | F3: =COUNTIFS(Signale!$A$2:$A$150,A3,Signale!$G$2:$G$150,"EGT") | G3: =C3-D3-E3-F3 | H3: =IF(B3="auf A und B",IF(AND(D3>0,E3>0),"ok","FEHLT auf "&IF(D3=0,"A","B")),IF(B3="ein Stecker",IF((D3>0)+(E3>0)+(F3>0)>1,"GETEILT",IF(G3>0,"teilweise unbelegt","ok")),"ok"))
A4: Sensormasse | B4: auf A und B | C4: =COUNTIF(Signale!$A$2:$A$150,A4) | D4: =COUNTIFS(Signale!$A$2:$A$150,A4,Signale!$G$2:$G$150,"A") | E4: =COUNTIFS(Signale!$A$2:$A$150,A4,Signale!$G$2:$G$150,"B") | F4: =COUNTIFS(Signale!$A$2:$A$150,A4,Signale!$G$2:$G$150,"EGT") | G4: =C4-D4-E4-F4 | H4: =IF(B4="auf A und B",IF(AND(D4>0,E4>0),"ok","FEHLT auf "&IF(D4=0,"A","B")),IF(B4="ein Stecker",IF((D4>0)+(E4>0)+(F4>0)>1,"GETEILT",IF(G4>0,"teilweise unbelegt","ok")),"ok"))
A5: Masse | B5: beliebig | C5: =COUNTIF(Signale!$A$2:$A$150,A5) | D5: =COUNTIFS(Signale!$A$2:$A$150,A5,Signale!$G$2:$G$150,"A") | E5: =COUNTIFS(Signale!$A$2:$A$150,A5,Signale!$G$2:$G$150,"B") | F5: =COUNTIFS(Signale!$A$2:$A$150,A5,Signale!$G$2:$G$150,"EGT") | G5: =C5-D5-E5-F5 | H5: =IF(B5="auf A und B",IF(AND(D5>0,E5>0),"ok","FEHLT auf "&IF(D5=0,"A","B")),IF(B5="ein Stecker",IF((D5>0)+(E5>0)+(F5>0)>1,"GETEILT",IF(G5>0,"teilweise unbelegt","ok")),"ok"))
A6: Einspritzung 1-2 | B6: ein Stecker | C6: =COUNTIF(Signale!$A$2:$A$150,A6) | D6: =COUNTIFS(Signale!$A$2:$A$150,A6,Signale!$G$2:$G$150,"A") | E6: =COUNTIFS(Signale!$A$2:$A$150,A6,Signale!$G$2:$G$150,"B") | F6: =COUNTIFS(Signale!$A$2:$A$150,A6,Signale!$G$2:$G$150,"EGT") | G6: =C6-D6-E6-F6 | H6: =IF(B6="auf A und B",IF(AND(D6>0,E6>0),"ok","FEHLT auf "&IF(D6=0,"A","B")),IF(B6="ein Stecker",IF((D6>0)+(E6>0)+(F6>0)>1,"GETEILT",IF(G6>0,"teilweise unbelegt","ok")),"ok"))
A7: Einspritzung 3-4 | B7: ein Stecker | C7: =COUNTIF(Signale!$A$2:$A$150,A7) | D7: =COUNTIFS(Signale!$A$2:$A$150,A7,Signale!$G$2:$G$150,"A") | E7: =COUNTIFS(Signale!$A$2:$A$150,A7,Signale!$G$2:$G$150,"B") | F7: =COUNTIFS(Signale!$A$2:$A$150,A7,Signale!$G$2:$G$150,"EGT") | G7: =C7-D7-E7-F7 | H7: =IF(B7="auf A und B",IF(AND(D7>0,E7>0),"ok","FEHLT auf "&IF(D7=0,"A","B")),IF(B7="ein Stecker",IF((D7>0)+(E7>0)+(F7>0)>1,"GETEILT",IF(G7>0,"teilweise unbelegt","ok")),"ok"))
A8: Einspritzung 5-6 (unbenutzt) | B8: beliebig | C8: =COUNTIF(Signale!$A$2:$A$150,A8) | D8: =COUNTIFS(Signale!$A$2:$A$150,A8,Signale!$G$2:$G$150,"A") | E8: =COUNTIFS(Signale!$A$2:$A$150,A8,Signale!$G$2:$G$150,"B") | F8: =COUNTIFS(Signale!$A$2:$A$150,A8,Signale!$G$2:$G$150,"EGT") | G8: =C8-D8-E8-F8 | H8: =IF(B8="auf A und B",IF(AND(D8>0,E8>0),"ok","FEHLT auf "&IF(D8=0,"A","B")),IF(B8="ein Stecker",IF((D8>0)+(E8>0)+(F8>0)>1,"GETEILT",IF(G8>0,"teilweise unbelegt","ok")),"ok"))
A9: Zündung 1-2 | B9: ein Stecker | C9: =COUNTIF(Signale!$A$2:$A$150,A9) | D9: =COUNTIFS(Signale!$A$2:$A$150,A9,Signale!$G$2:$G$150,"A") | E9: =COUNTIFS(Signale!$A$2:$A$150,A9,Signale!$G$2:$G$150,"B") | F9: =COUNTIFS(Signale!$A$2:$A$150,A9,Signale!$G$2:$G$150,"EGT") | G9: =C9-D9-E9-F9 | H9: =IF(B9="auf A und B",IF(AND(D9>0,E9>0),"ok","FEHLT auf "&IF(D9=0,"A","B")),IF(B9="ein Stecker",IF((D9>0)+(E9>0)+(F9>0)>1,"GETEILT",IF(G9>0,"teilweise unbelegt","ok")),"ok"))
A10: Zündung 3-4 | B10: ein Stecker | C10: =COUNTIF(Signale!$A$2:$A$150,A10) | D10: =COUNTIFS(Signale!$A$2:$A$150,A10,Signale!$G$2:$G$150,"A") | E10: =COUNTIFS(Signale!$A$2:$A$150,A10,Signale!$G$2:$G$150,"B") | F10: =COUNTIFS(Signale!$A$2:$A$150,A10,Signale!$G$2:$G$150,"EGT") | G10: =C10-D10-E10-F10 | H10: =IF(B10="auf A und B",IF(AND(D10>0,E10>0),"ok","FEHLT auf "&IF(D10=0,"A","B")),IF(B10="ein Stecker",IF((D10>0)+(E10>0)+(F10>0)>1,"GETEILT",IF(G10>0,"teilweise unbelegt","ok")),"ok"))
A11: Zündung 5-6 (unbenutzt) | B11: beliebig | C11: =COUNTIF(Signale!$A$2:$A$150,A11) | D11: =COUNTIFS(Signale!$A$2:$A$150,A11,Signale!$G$2:$G$150,"A") | E11: =COUNTIFS(Signale!$A$2:$A$150,A11,Signale!$G$2:$G$150,"B") | F11: =COUNTIFS(Signale!$A$2:$A$150,A11,Signale!$G$2:$G$150,"EGT") | G11: =C11-D11-E11-F11 | H11: =IF(B11="auf A und B",IF(AND(D11>0,E11>0),"ok","FEHLT auf "&IF(D11=0,"A","B")),IF(B11="ein Stecker",IF((D11>0)+(E11>0)+(F11>0)>1,"GETEILT",IF(G11>0,"teilweise unbelegt","ok")),"ok"))
A12: GPPWM 1-2 | B12: ein Stecker | C12: =COUNTIF(Signale!$A$2:$A$150,A12) | D12: =COUNTIFS(Signale!$A$2:$A$150,A12,Signale!$G$2:$G$150,"A") | E12: =COUNTIFS(Signale!$A$2:$A$150,A12,Signale!$G$2:$G$150,"B") | F12: =COUNTIFS(Signale!$A$2:$A$150,A12,Signale!$G$2:$G$150,"EGT") | G12: =C12-D12-E12-F12 | H12: =IF(B12="auf A und B",IF(AND(D12>0,E12>0),"ok","FEHLT auf "&IF(D12=0,"A","B")),IF(B12="ein Stecker",IF((D12>0)+(E12>0)+(F12>0)>1,"GETEILT",IF(G12>0,"teilweise unbelegt","ok")),"ok"))
A13: GPPWM 3-4 | B13: ein Stecker | C13: =COUNTIF(Signale!$A$2:$A$150,A13) | D13: =COUNTIFS(Signale!$A$2:$A$150,A13,Signale!$G$2:$G$150,"A") | E13: =COUNTIFS(Signale!$A$2:$A$150,A13,Signale!$G$2:$G$150,"B") | F13: =COUNTIFS(Signale!$A$2:$A$150,A13,Signale!$G$2:$G$150,"EGT") | G13: =C13-D13-E13-F13 | H13: =IF(B13="auf A und B",IF(AND(D13>0,E13>0),"ok","FEHLT auf "&IF(D13=0,"A","B")),IF(B13="ein Stecker",IF((D13>0)+(E13>0)+(F13>0)>1,"GETEILT",IF(G13>0,"teilweise unbelegt","ok")),"ok"))
... A33: Reserve MCU | B33: beliebig | C33: =COUNTIF(Signale!$A$2:$A$150,A33) | D33: =COUNTIFS(Signale!$A$2:$A$150,A33,Signale!$G$2:$G$150,"A") | E33: =COUNTIFS(Signale!$A$2:$A$150,A33,Signale!$G$2:$G$150,"B") | F33: =COUNTIFS(Signale!$A$2:$A$150,A33,Signale!$G$2:$G$150,"EGT") | G33: =C33-D33-E33-F33 | H33: =IF(B33="auf A und B",IF(AND(D33>0,E33>0),"ok","FEHLT auf "&IF(D33=0,"A","B")),IF(B33="ein Stecker",IF((D33>0)+(E33>0)+(F33>0)>1,"GETEILT",IF(G33>0,"teilweise unbelegt","ok")),"ok"))
A35: Belegte Pins | D35: ='Stecker A'!B37 | E35: ='Stecker B'!B37 | F35: =EGT!B11
A36: Doppelt belegte Signale | D36: =COUNTIF(Signale!$K$2:$K$150,"DOPPELT")
A37: Regelverstöße Gruppen | D37: =COUNTIF(H2:H33,"GETEILT")+COUNTIF(H2:H33,"FEHLT*")

Sheet Stecker A
A1: Pin | B1: Signal | C1: Gruppe | D1: Netz | E1: Typ | F1: Strom max | G1: Belegung | H1: Kabelfarbe | I1: Querschnitt mm²
A2: 1 | B2: =IFERROR(INDEX(Signale!$B$2:$B$150,MATCH("A-1",Signale!$J$2:$J$150,0)),"") | C2: =IFERROR(INDEX(Signale!$A$2:$A$150,MATCH("A-1",Signale!$J$2:$J$150,0)),"") | D2: =IFERROR(INDEX(Signale!$C$2:$C$150,MATCH("A-1",Signale!$J$2:$J$150,0)),"") | E2: =IFERROR(INDEX(Signale!$E$2:$E$150,MATCH("A-1",Signale!$J$2:$J$150,0)),"") | F2: =IFERROR(INDEX(Signale!$F$2:$F$150,MATCH("A-1",Signale!$J$2:$J$150,0)),"") | G2: =IF(COUNTIF(Signale!$J$2:$J$150,"A-1")=0,"frei",IF(COUNTIF(Signale!$J$2:$J$150,"A-1")>1,"DOPPELT","belegt")) | H2: =IFERROR(IF(INDEX(Signale!$L$2:$L$150,MATCH("A-1",Signale!$J$2:$J$150,0))="","",INDEX(Signale!$L$2:$L$150,MATCH("A-1",Signale!$J$2:$J$150,0))),"") | I2: =IFERROR(IF(INDEX(Signale!$M$2:$M$150,MATCH("A-1",Signale!$J$2:$J$150,0))="","",INDEX(Signale!$M$2:$M$150,MATCH("A-1",Signale!$J$2:$J$150,0))),"")
A3: 2 | B3: =IFERROR(INDEX(Signale!$B$2:$B$150,MATCH("A-2",Signale!$J$2:$J$150,0)),"") | C3: =IFERROR(INDEX(Signale!$A$2:$A$150,MATCH("A-2",Signale!$J$2:$J$150,0)),"") | D3: =IFERROR(INDEX(Signale!$C$2:$C$150,MATCH("A-2",Signale!$J$2:$J$150,0)),"") | E3: =IFERROR(INDEX(Signale!$E$2:$E$150,MATCH("A-2",Signale!$J$2:$J$150,0)),"") | F3: =IFERROR(INDEX(Signale!$F$2:$F$150,MATCH("A-2",Signale!$J$2:$J$150,0)),"") | G3: =IF(COUNTIF(Signale!$J$2:$J$150,"A-2")=0,"frei",IF(COUNTIF(Signale!$J$2:$J$150,"A-2")>1,"DOPPELT","belegt")) | H3: =IFERROR(IF(INDEX(Signale!$L$2:$L$150,MATCH("A-2",Signale!$J$2:$J$150,0))="","",INDEX(Signale!$L$2:$L$150,MATCH("A-2",Signale!$J$2:$J$150,0))),"") | I3: =IFERROR(IF(INDEX(Signale!$M$2:$M$150,MATCH("A-2",Signale!$J$2:$J$150,0))="","",INDEX(Signale!$M$2:$M$150,MATCH("A-2",Signale!$J$2:$J$150,0))),"")
A4: 3 | B4: =IFERROR(INDEX(Signale!$B$2:$B$150,MATCH("A-3",Signale!$J$2:$J$150,0)),"") | C4: =IFERROR(INDEX(Signale!$A$2:$A$150,MATCH("A-3",Signale!$J$2:$J$150,0)),"") | D4: =IFERROR(INDEX(Signale!$C$2:$C$150,MATCH("A-3",Signale!$J$2:$J$150,0)),"") | E4: =IFERROR(INDEX(Signale!$E$2:$E$150,MATCH("A-3",Signale!$J$2:$J$150,0)),"") | F4: =IFERROR(INDEX(Signale!$F$2:$F$150,MATCH("A-3",Signale!$J$2:$J$150,0)),"") | G4: =IF(COUNTIF(Signale!$J$2:$J$150,"A-3")=0,"frei",IF(COUNTIF(Signale!$J$2:$J$150,"A-3")>1,"DOPPELT","belegt")) | H4: =IFERROR(IF(INDEX(Signale!$L$2:$L$150,MATCH("A-3",Signale!$J$2:$J$150,0))="","",INDEX(Signale!$L$2:$L$150,MATCH("A-3",Signale!$J$2:$J$150,0))),"") | I4: =IFERROR(IF(INDEX(Signale!$M$2:$M$150,MATCH("A-3",Signale!$J$2:$J$150,0))="","",INDEX(Signale!$M$2:$M$150,MATCH("A-3",Signale!$J$2:$J$150,0))),"")
A5: 4 | B5: =IFERROR(INDEX(Signale!$B$2:$B$150,MATCH("A-4",Signale!$J$2:$J$150,0)),"") | C5: =IFERROR(INDEX(Signale!$A$2:$A$150,MATCH("A-4",Signale!$J$2:$J$150,0)),"") | D5: =IFERROR(INDEX(Signale!$C$2:$C$150,MATCH("A-4",Signale!$J$2:$J$150,0)),"") | E5: =IFERROR(INDEX(Signale!$E$2:$E$150,MATCH("A-4",Signale!$J$2:$J$150,0)),"") | F5: =IFERROR(INDEX(Signale!$F$2:$F$150,MATCH("A-4",Signale!$J$2:$J$150,0)),"") | G5: =IF(COUNTIF(Signale!$J$2:$J$150,"A-4")=0,"frei",IF(COUNTIF(Signale!$J$2:$J$150,"A-4")>1,"DOPPELT","belegt")) | H5: =IFERROR(IF(INDEX(Signale!$L$2:$L$150,MATCH("A-4",Signale!$J$2:$J$150,0))="","",INDEX(Signale!$L$2:$L$150,MATCH("A-4",Signale!$J$2:$J$150,0))),"") | I5: =IFERROR(IF(INDEX(Signale!$M$2:$M$150,MATCH("A-4",Signale!$J$2:$J$150,0))="","",INDEX(Signale!$M$2:$M$150,MATCH("A-4",Signale!$J$2:$J$150,0))),"")
A6: 5 | B6: =IFERROR(INDEX(Signale!$B$2:$B$150,MATCH("A-5",Signale!$J$2:$J$150,0)),"") | C6: =IFERROR(INDEX(Signale!$A$2:$A$150,MATCH("A-5",Signale!$J$2:$J$150,0)),"") | D6: =IFERROR(INDEX(Signale!$C$2:$C$150,MATCH("A-5",Signale!$J$2:$J$150,0)),"") | E6: =IFERROR(INDEX(Signale!$E$2:$E$150,MATCH("A-5",Signale!$J$2:$J$150,0)),"") | F6: =IFERROR(INDEX(Signale!$F$2:$F$150,MATCH("A-5",Signale!$J$2:$J$150,0)),"") | G6: =IF(COUNTIF(Signale!$J$2:$J$150,"A-5")=0,"frei",IF(COUNTIF(Signale!$J$2:$J$150,"A-5")>1,"DOPPELT","belegt")) | H6: =IFERROR(IF(INDEX(Signale!$L$2:$L$150,MATCH("A-5",Signale!$J$2:$J$150,0))="","",INDEX(Signale!$L$2:$L$150,MATCH("A-5",Signale!$J$2:$J$150,0))),"") | I6: =IFERROR(IF(INDEX(Signale!$M$2:$M$150,MATCH("A-5",Signale!$J$2:$J$150,0))="","",INDEX(Signale!$M$2:$M$150,MATCH("A-5",Signale!$J$2:$J$150,0))),"")
A7: 6 | B7: =IFERROR(INDEX(Signale!$B$2:$B$150,MATCH("A-6",Signale!$J$2:$J$150,0)),"") | C7: =IFERROR(INDEX(Signale!$A$2:$A$150,MATCH("A-6",Signale!$J$2:$J$150,0)),"") | D7: =IFERROR(INDEX(Signale!$C$2:$C$150,MATCH("A-6",Signale!$J$2:$J$150,0)),"") | E7: =IFERROR(INDEX(Signale!$E$2:$E$150,MATCH("A-6",Signale!$J$2:$J$150,0)),"") | F7: =IFERROR(INDEX(Signale!$F$2:$F$150,MATCH("A-6",Signale!$J$2:$J$150,0)),"") | G7: =IF(COUNTIF(Signale!$J$2:$J$150,"A-6")=0,"frei",IF(COUNTIF(Signale!$J$2:$J$150,"A-6")>1,"DOPPELT","belegt")) | H7: =IFERROR(IF(INDEX(Signale!$L$2:$L$150,MATCH("A-6",Signale!$J$2:$J$150,0))="","",INDEX(Signale!$L$2:$L$150,MATCH("A-6",Signale!$J$2:$J$150,0))),"") | I7: =IFERROR(IF(INDEX(Signale!$M$2:$M$150,MATCH("A-6",Signale!$J$2:$J$150,0))="","",INDEX(Signale!$M$2:$M$150,MATCH("A-6",Signale!$J$2:$J$150,0))),"")
A8: 7 | B8: =IFERROR(INDEX(Signale!$B$2:$B$150,MATCH("A-7",Signale!$J$2:$J$150,0)),"") | C8: =IFERROR(INDEX(Signale!$A$2:$A$150,MATCH("A-7",Signale!$J$2:$J$150,0)),"") | D8: =IFERROR(INDEX(Signale!$C$2:$C$150,MATCH("A-7",Signale!$J$2:$J$150,0)),"") | E8: =IFERROR(INDEX(Signale!$E$2:$E$150,MATCH("A-7",Signale!$J$2:$J$150,0)),"") | F8: =IFERROR(INDEX(Signale!$F$2:$F$150,MATCH("A-7",Signale!$J$2:$J$150,0)),"") | G8: =IF(COUNTIF(Signale!$J$2:$J$150,"A-7")=0,"frei",IF(COUNTIF(Signale!$J$2:$J$150,"A-7")>1,"DOPPELT","belegt")) | H8: =IFERROR(IF(INDEX(Signale!$L$2:$L$150,MATCH("A-7",Signale!$J$2:$J$150,0))="","",INDEX(Signale!$L$2:$L$150,MATCH("A-7",Signale!$J$2:$J$150,0))),"") | I8: =IFERROR(IF(INDEX(Signale!$M$2:$M$150,MATCH("A-7",Signale!$J$2:$J$150,0))="","",INDEX(Signale!$M$2:$M$150,MATCH("A-7",Signale!$J$2:$J$150,0))),"")
A9: 8 | B9: =IFERROR(INDEX(Signale!$B$2:$B$150,MATCH("A-8",Signale!$J$2:$J$150,0)),"") | C9: =IFERROR(INDEX(Signale!$A$2:$A$150,MATCH("A-8",Signale!$J$2:$J$150,0)),"") | D9: =IFERROR(INDEX(Signale!$C$2:$C$150,MATCH("A-8",Signale!$J$2:$J$150,0)),"") | E9: =IFERROR(INDEX(Signale!$E$2:$E$150,MATCH("A-8",Signale!$J$2:$J$150,0)),"") | F9: =IFERROR(INDEX(Signale!$F$2:$F$150,MATCH("A-8",Signale!$J$2:$J$150,0)),"") | G9: =IF(COUNTIF(Signale!$J$2:$J$150,"A-8")=0,"frei",IF(COUNTIF(Signale!$J$2:$J$150,"A-8")>1,"DOPPELT","belegt")) | H9: =IFERROR(IF(INDEX(Signale!$L$2:$L$150,MATCH("A-8",Signale!$J$2:$J$150,0))="","",INDEX(Signale!$L$2:$L$150,MATCH("A-8",Signale!$J$2:$J$150,0))),"") | I9: =IFERROR(IF(INDEX(Signale!$M$2:$M$150,MATCH("A-8",Signale!$J$2:$J$150,0))="","",INDEX(Signale!$M$2:$M$150,MATCH("A-8",Signale!$J$2:$J$150,0))),"")
A10: 9 | B10: =IFERROR(INDEX(Signale!$B$2:$B$150,MATCH("A-9",Signale!$J$2:$J$150,0)),"") | C10: =IFERROR(INDEX(Signale!$A$2:$A$150,MATCH("A-9",Signale!$J$2:$J$150,0)),"") | D10: =IFERROR(INDEX(Signale!$C$2:$C$150,MATCH("A-9",Signale!$J$2:$J$150,0)),"") | E10: =IFERROR(INDEX(Signale!$E$2:$E$150,MATCH("A-9",Signale!$J$2:$J$150,0)),"") | F10: =IFERROR(INDEX(Signale!$F$2:$F$150,MATCH("A-9",Signale!$J$2:$J$150,0)),"") | G10: =IF(COUNTIF(Signale!$J$2:$J$150,"A-9")=0,"frei",IF(COUNTIF(Signale!$J$2:$J$150,"A-9")>1,"DOPPELT","belegt")) | H10: =IFERROR(IF(INDEX(Signale!$L$2:$L$150,MATCH("A-9",Signale!$J$2:$J$150,0))="","",INDEX(Signale!$L$2:$L$150,MATCH("A-9",Signale!$J$2:$J$150,0))),"") | I10: =IFERROR(IF(INDEX(Signale!$M$2:$M$150,MATCH("A-9",Signale!$J$2:$J$150,0))="","",INDEX(Signale!$M$2:$M$150,MATCH("A-9",Signale!$J$2:$J$150,0))),"")
A11: 10 | B11: =IFERROR(INDEX(Signale!$B$2:$B$150,MATCH("A-10",Signale!$J$2:$J$150,0)),"") | C11: =IFERROR(INDEX(Signale!$A$2:$A$150,MATCH("A-10",Signale!$J$2:$J$150,0)),"") | D11: =IFERROR(INDEX(Signale!$C$2:$C$150,MATCH("A-10",Signale!$J$2:$J$150,0)),"") | E11: =IFERROR(INDEX(Signale!$E$2:$E$150,MATCH("A-10",Signale!$J$2:$J$150,0)),"") | F11: =IFERROR(INDEX(Signale!$F$2:$F$150,MATCH("A-10",Signale!$J$2:$J$150,0)),"") | G11: =IF(COUNTIF(Signale!$J$2:$J$150,"A-10")=0,"frei",IF(COUNTIF(Signale!$J$2:$J$150,"A-10")>1,"DOPPELT","belegt")) | H11: =IFERROR(IF(INDEX(Signale!$L$2:$L$150,MATCH("A-10",Signale!$J$2:$J$150,0))="","",INDEX(Signale!$L$2:$L$150,MATCH("A-10",Signale!$J$2:$J$150,0))),"") | I11: =IFERROR(IF(INDEX(Signale!$M$2:$M$150,MATCH("A-10",Signale!$J$2:$J$150,0))="","",INDEX(Signale!$M$2:$M$150,MATCH("A-10",Signale!$J$2:$J$150,0))),"")
A12: 11 | B12: =IFERROR(INDEX(Signale!$B$2:$B$150,MATCH("A-11",Signale!$J$2:$J$150,0)),"") | C12: =IFERROR(INDEX(Signale!$A$2:$A$150,MATCH("A-11",Signale!$J$2:$J$150,0)),"") | D12: =IFERROR(INDEX(Signale!$C$2:$C$150,MATCH("A-11",Signale!$J$2:$J$150,0)),"") | E12: =IFERROR(INDEX(Signale!$E$2:$E$150,MATCH("A-11",Signale!$J$2:$J$150,0)),"") | F12: =IFERROR(INDEX(Signale!$F$2:$F$150,MATCH("A-11",Signale!$J$2:$J$150,0)),"") | G12: =IF(COUNTIF(Signale!$J$2:$J$150,"A-11")=0,"frei",IF(COUNTIF(Signale!$J$2:$J$150,"A-11")>1,"DOPPELT","belegt")) | H12: =IFERROR(IF(INDEX(Signale!$L$2:$L$150,MATCH("A-11",Signale!$J$2:$J$150,0))="","",INDEX(Signale!$L$2:$L$150,MATCH("A-11",Signale!$J$2:$J$150,0))),"") | I12: =IFERROR(IF(INDEX(Signale!$M$2:$M$150,MATCH("A-11",Signale!$J$2:$J$150,0))="","",INDEX(Signale!$M$2:$M$150,MATCH("A-11",Signale!$J$2:$J$150,0))),"")
A13: 12 | B13: =IFERROR(INDEX(Signale!$B$2:$B$150,MATCH("A-12",Signale!$J$2:$J$150,0)),"") | C13: =IFERROR(INDEX(Signale!$A$2:$A$150,MATCH("A-12",Signale!$J$2:$J$150,0)),"") | D13: =IFERROR(INDEX(Signale!$C$2:$C$150,MATCH("A-12",Signale!$J$2:$J$150,0)),"") | E13: =IFERROR(INDEX(Signale!$E$2:$E$150,MATCH("A-12",Signale!$J$2:$J$150,0)),"") | F13: =IFERROR(INDEX(Signale!$F$2:$F$150,MATCH("A-12",Signale!$J$2:$J$150,0)),"") | G13: =IF(COUNTIF(Signale!$J$2:$J$150,"A-12")=0,"frei",IF(COUNTIF(Signale!$J$2:$J$150,"A-12")>1,"DOPPELT","belegt")) | H13: =IFERROR(IF(INDEX(Signale!$L$2:$L$150,MATCH("A-12",Signale!$J$2:$J$150,0))="","",INDEX(Signale!$L$2:$L$150,MATCH("A-12",Signale!$J$2:$J$150,0))),"") | I13: =IFERROR(IF(INDEX(Signale!$M$2:$M$150,MATCH("A-12",Signale!$J$2:$J$150,0))="","",INDEX(Signale!$M$2:$M$150,MATCH("A-12",Signale!$J$2:$J$150,0))),"")
A14: 13 | B14: =IFERROR(INDEX(Signale!$B$2:$B$150,MATCH("A-13",Signale!$J$2:$J$150,0)),"") | C14: =IFERROR(INDEX(Signale!$A$2:$A$150,MATCH("A-13",Signale!$J$2:$J$150,0)),"") | D14: =IFERROR(INDEX(Signale!$C$2:$C$150,MATCH("A-13",Signale!$J$2:$J$150,0)),"") | E14: =IFERROR(INDEX(Signale!$E$2:$E$150,MATCH("A-13",Signale!$J$2:$J$150,0)),"") | F14: =IFERROR(INDEX(Signale!$F$2:$F$150,MATCH("A-13",Signale!$J$2:$J$150,0)),"") | G14: =IF(COUNTIF(Signale!$J$2:$J$150,"A-13")=0,"frei",IF(COUNTIF(Signale!$J$2:$J$150,"A-13")>1,"DOPPELT","belegt")) | H14: =IFERROR(IF(INDEX(Signale!$L$2:$L$150,MATCH("A-13",Signale!$J$2:$J$150,0))="","",INDEX(Signale!$L$2:$L$150,MATCH("A-13",Signale!$J$2:$J$150,0))),"") | I14: =IFERROR(IF(INDEX(Signale!$M$2:$M$150,MATCH("A-13",Signale!$J$2:$J$150,0))="","",INDEX(Signale!$M$2:$M$150,MATCH("A-13",Signale!$J$2:$J$150,0))),"")
A15: 14 | B15: =IFERROR(INDEX(Signale!$B$2:$B$150,MATCH("A-14",Signale!$J$2:$J$150,0)),"") | C15: =IFERROR(INDEX(Signale!$A$2:$A$150,MATCH("A-14",Signale!$J$2:$J$150,0)),"") | D15: =IFERROR(INDEX(Signale!$C$2:$C$150,MATCH("A-14",Signale!$J$2:$J$150,0)),"") | E15: =IFERROR(INDEX(Signale!$E$2:$E$150,MATCH("A-14",Signale!$J$2:$J$150,0)),"") | F15: =IFERROR(INDEX(Signale!$F$2:$F$150,MATCH("A-14",Signale!$J$2:$J$150,0)),"") | G15: =IF(COUNTIF(Signale!$J$2:$J$150,"A-14")=0,"frei",IF(COUNTIF(Signale!$J$2:$J$150,"A-14")>1,"DOPPELT","belegt")) | H15: =IFERROR(IF(INDEX(Signale!$L$2:$L$150,MATCH("A-14",Signale!$J$2:$J$150,0))="","",INDEX(Signale!$L$2:$L$150,MATCH("A-14",Signale!$J$2:$J$150,0))),"") | I15: =IFERROR(IF(INDEX(Signale!$M$2:$M$150,MATCH("A-14",Signale!$J$2:$J$150,0))="","",INDEX(Signale!$M$2:$M$150,MATCH("A-14",Signale!$J$2:$J$150,0))),"")
A16: 15 | B16: =IFERROR(INDEX(Signale!$B$2:$B$150,MATCH("A-15",Signale!$J$2:$J$150,0)),"") | C16: =IFERROR(INDEX(Signale!$A$2:$A$150,MATCH("A-15",Signale!$J$2:$J$150,0)),"") | D16: =IFERROR(INDEX(Signale!$C$2:$C$150,MATCH("A-15",Signale!$J$2:$J$150,0)),"") | E16: =IFERROR(INDEX(Signale!$E$2:$E$150,MATCH("A-15",Signale!$J$2:$J$150,0)),"") | F16: =IFERROR(INDEX(Signale!$F$2:$F$150,MATCH("A-15",Signale!$J$2:$J$150,0)),"") | G16: =IF(COUNTIF(Signale!$J$2:$J$150,"A-15")=0,"frei",IF(COUNTIF(Signale!$J$2:$J$150,"A-15")>1,"DOPPELT","belegt")) | H16: =IFERROR(IF(INDEX(Signale!$L$2:$L$150,MATCH("A-15",Signale!$J$2:$J$150,0))="","",INDEX(Signale!$L$2:$L$150,MATCH("A-15",Signale!$J$2:$J$150,0))),"") | I16: =IFERROR(IF(INDEX(Signale!$M$2:$M$150,MATCH("A-15",Signale!$J$2:$J$150,0))="","",INDEX(Signale!$M$2:$M$150,MATCH("A-15",Signale!$J$2:$J$150,0))),"")
A17: 16 | B17: =IFERROR(INDEX(Signale!$B$2:$B$150,MATCH("A-16",Signale!$J$2:$J$150,0)),"") | C17: =IFERROR(INDEX(Signale!$A$2:$A$150,MATCH("A-16",Signale!$J$2:$J$150,0)),"") | D17: =IFERROR(INDEX(Signale!$C$2:$C$150,MATCH("A-16",Signale!$J$2:$J$150,0)),"") | E17: =IFERROR(INDEX(Signale!$E$2:$E$150,MATCH("A-16",Signale!$J$2:$J$150,0)),"") | F17: =IFERROR(INDEX(Signale!$F$2:$F$150,MATCH("A-16",Signale!$J$2:$J$150,0)),"") | G17: =IF(COUNTIF(Signale!$J$2:$J$150,"A-16")=0,"frei",IF(COUNTIF(Signale!$J$2:$J$150,"A-16")>1,"DOPPELT","belegt")) | H17: =IFERROR(IF(INDEX(Signale!$L$2:$L$150,MATCH("A-16",Signale!$J$2:$J$150,0))="","",INDEX(Signale!$L$2:$L$150,MATCH("A-16",Signale!$J$2:$J$150,0))),"") | I17: =IFERROR(IF(INDEX(Signale!$M$2:$M$150,MATCH("A-16",Signale!$J$2:$J$150,0))="","",INDEX(Signale!$M$2:$M$150,MATCH("A-16",Signale!$J$2:$J$150,0))),"")
A18: 17 | B18: =IFERROR(INDEX(Signale!$B$2:$B$150,MATCH("A-17",Signale!$J$2:$J$150,0)),"") | C18: =IFERROR(INDEX(Signale!$A$2:$A$150,MATCH("A-17",Signale!$J$2:$J$150,0)),"") | D18: =IFERROR(INDEX(Signale!$C$2:$C$150,MATCH("A-17",Signale!$J$2:$J$150,0)),"") | E18: =IFERROR(INDEX(Signale!$E$2:$E$150,MATCH("A-17",Signale!$J$2:$J$150,0)),"") | F18: =IFERROR(INDEX(Signale!$F$2:$F$150,MATCH("A-17",Signale!$J$2:$J$150,0)),"") | G18: =IF(COUNTIF(Signale!$J$2:$J$150,"A-17")=0,"frei",IF(COUNTIF(Signale!$J$2:$J$150,"A-17")>1,"DOPPELT","belegt")) | H18: =IFERROR(IF(INDEX(Signale!$L$2:$L$150,MATCH("A-17",Signale!$J$2:$J$150,0))="","",INDEX(Signale!$L$2:$L$150,MATCH("A-17",Signale!$J$2:$J$150,0))),"") | I18: =IFERROR(IF(INDEX(Signale!$M$2:$M$150,MATCH("A-17",Signale!$J$2:$J$150,0))="","",INDEX(Signale!$M$2:$M$150,MATCH("A-17",Signale!$J$2:$J$150,0))),"")
A19: 18 | B19: =IFERROR(INDEX(Signale!$B$2:$B$150,MATCH("A-18",Signale!$J$2:$J$150,0)),"") | C19: =IFERROR(INDEX(Signale!$A$2:$A$150,MATCH("A-18",Signale!$J$2:$J$150,0)),"") | D19: =IFERROR(INDEX(Signale!$C$2:$C$150,MATCH("A-18",Signale!$J$2:$J$150,0)),"") | E19: =IFERROR(INDEX(Signale!$E$2:$E$150,MATCH("A-18",Signale!$J$2:$J$150,0)),"") | F19: =IFERROR(INDEX(Signale!$F$2:$F$150,MATCH("A-18",Signale!$J$2:$J$150,0)),"") | G19: =IF(COUNTIF(Signale!$J$2:$J$150,"A-18")=0,"frei",IF(COUNTIF(Signale!$J$2:$J$150,"A-18")>1,"DOPPELT","belegt")) | H19: =IFERROR(IF(INDEX(Signale!$L$2:$L$150,MATCH("A-18",Signale!$J$2:$J$150,0))="","",INDEX(Signale!$L$2:$L$150,MATCH("A-18",Signale!$J$2:$J$150,0))),"") | I19: =IFERROR(IF(INDEX(Signale!$M$2:$M$150,MATCH("A-18",Signale!$J$2:$J$150,0))="","",INDEX(Signale!$M$2:$M$150,MATCH("A-18",Signale!$J$2:$J$150,0))),"")
A20: 19 | B20: =IFERROR(INDEX(Signale!$B$2:$B$150,MATCH("A-19",Signale!$J$2:$J$150,0)),"") | C20: =IFERROR(INDEX(Signale!$A$2:$A$150,MATCH("A-19",Signale!$J$2:$J$150,0)),"") | D20: =IFERROR(INDEX(Signale!$C$2:$C$150,MATCH("A-19",Signale!$J$2:$J$150,0)),"") | E20: =IFERROR(INDEX(Signale!$E$2:$E$150,MATCH("A-19",Signale!$J$2:$J$150,0)),"") | F20: =IFERROR(INDEX(Signale!$F$2:$F$150,MATCH("A-19",Signale!$J$2:$J$150,0)),"") | G20: =IF(COUNTIF(Signale!$J$2:$J$150,"A-19")=0,"frei",IF(COUNTIF(Signale!$J$2:$J$150,"A-19")>1,"DOPPELT","belegt")) | H20: =IFERROR(IF(INDEX(Signale!$L$2:$L$150,MATCH("A-19",Signale!$J$2:$J$150,0))="","",INDEX(Signale!$L$2:$L$150,MATCH("A-19",Signale!$J$2:$J$150,0))),"") | I20: =IFERROR(IF(INDEX(Signale!$M$2:$M$150,MATCH("A-19",Signale!$J$2:$J$150,0))="","",INDEX(Signale!$M$2:$M$150,MATCH("A-19",Signale!$J$2:$J$150,0))),"")
A21: 20 | B21: =IFERROR(INDEX(Signale!$B$2:$B$150,MATCH("A-20",Signale!$J$2:$J$150,0)),"") | C21: =IFERROR(INDEX(Signale!$A$2:$A$150,MATCH("A-20",Signale!$J$2:$J$150,0)),"") | D21: =IFERROR(INDEX(Signale!$C$2:$C$150,MATCH("A-20",Signale!$J$2:$J$150,0)),"") | E21: =IFERROR(INDEX(Signale!$E$2:$E$150,MATCH("A-20",Signale!$J$2:$J$150,0)),"") | F21: =IFERROR(INDEX(Signale!$F$2:$F$150,MATCH("A-20",Signale!$J$2:$J$150,0)),"") | G21: =IF(COUNTIF(Signale!$J$2:$J$150,"A-20")=0,"frei",IF(COUNTIF(Signale!$J$2:$J$150,"A-20")>1,"DOPPELT","belegt")) | H21: =IFERROR(IF(INDEX(Signale!$L$2:$L$150,MATCH("A-20",Signale!$J$2:$J$150,0))="","",INDEX(Signale!$L$2:$L$150,MATCH("A-20",Signale!$J$2:$J$150,0))),"") | I21: =IFERROR(IF(INDEX(Signale!$M$2:$M$150,MATCH("A-20",Signale!$J$2:$J$150,0))="","",INDEX(Signale!$M$2:$M$150,MATCH("A-20",Signale!$J$2:$J$150,0))),"")
A22: 21 | B22: =IFERROR(INDEX(Signale!$B$2:$B$150,MATCH("A-21",Signale!$J$2:$J$150,0)),"") | C22: =IFERROR(INDEX(Signale!$A$2:$A$150,MATCH("A-21",Signale!$J$2:$J$150,0)),"") | D22: =IFERROR(INDEX(Signale!$C$2:$C$150,MATCH("A-21",Signale!$J$2:$J$150,0)),"") | E22: =IFERROR(INDEX(Signale!$E$2:$E$150,MATCH("A-21",Signale!$J$2:$J$150,0)),"") | F22: =IFERROR(INDEX(Signale!$F$2:$F$150,MATCH("A-21",Signale!$J$2:$J$150,0)),"") | G22: =IF(COUNTIF(Signale!$J$2:$J$150,"A-21")=0,"frei",IF(COUNTIF(Signale!$J$2:$J$150,"A-21")>1,"DOPPELT","belegt")) | H22: =IFERROR(IF(INDEX(Signale!$L$2:$L$150,MATCH("A-21",Signale!$J$2:$J$150,0))="","",INDEX(Signale!$L$2:$L$150,MATCH("A-21",Signale!$J$2:$J$150,0))),"") | I22: =IFERROR(IF(INDEX(Signale!$M$2:$M$150,MATCH("A-21",Signale!$J$2:$J$150,0))="","",INDEX(Signale!$M$2:$M$150,MATCH("A-21",Signale!$J$2:$J$150,0))),"")
A23: 22 | B23: =IFERROR(INDEX(Signale!$B$2:$B$150,MATCH("A-22",Signale!$J$2:$J$150,0)),"") | C23: =IFERROR(INDEX(Signale!$A$2:$A$150,MATCH("A-22",Signale!$J$2:$J$150,0)),"") | D23: =IFERROR(INDEX(Signale!$C$2:$C$150,MATCH("A-22",Signale!$J$2:$J$150,0)),"") | E23: =IFERROR(INDEX(Signale!$E$2:$E$150,MATCH("A-22",Signale!$J$2:$J$150,0)),"") | F23: =IFERROR(INDEX(Signale!$F$2:$F$150,MATCH("A-22",Signale!$J$2:$J$150,0)),"") | G23: =IF(COUNTIF(Signale!$J$2:$J$150,"A-22")=0,"frei",IF(COUNTIF(Signale!$J$2:$J$150,"A-22")>1,"DOPPELT","belegt")) | H23: =IFERROR(IF(INDEX(Signale!$L$2:$L$150,MATCH("A-22",Signale!$J$2:$J$150,0))="","",INDEX(Signale!$L$2:$L$150,MATCH("A-22",Signale!$J$2:$J$150,0))),"") | I23: =IFERROR(IF(INDEX(Signale!$M$2:$M$150,MATCH("A-22",Signale!$J$2:$J$150,0))="","",INDEX(Signale!$M$2:$M$150,MATCH("A-22",Signale!$J$2:$J$150,0))),"")
A24: 23 | B24: =IFERROR(INDEX(Signale!$B$2:$B$150,MATCH("A-23",Signale!$J$2:$J$150,0)),"") | C24: =IFERROR(INDEX(Signale!$A$2:$A$150,MATCH("A-23",Signale!$J$2:$J$150,0)),"") | D24: =IFERROR(INDEX(Signale!$C$2:$C$150,MATCH("A-23",Signale!$J$2:$J$150,0)),"") | E24: =IFERROR(INDEX(Signale!$E$2:$E$150,MATCH("A-23",Signale!$J$2:$J$150,0)),"") | F24: =IFERROR(INDEX(Signale!$F$2:$F$150,MATCH("A-23",Signale!$J$2:$J$150,0)),"") | G24: =IF(COUNTIF(Signale!$J$2:$J$150,"A-23")=0,"frei",IF(COUNTIF(Signale!$J$2:$J$150,"A-23")>1,"DOPPELT","belegt")) | H24: =IFERROR(IF(INDEX(Signale!$L$2:$L$150,MATCH("A-23",Signale!$J$2:$J$150,0))="","",INDEX(Signale!$L$2:$L$150,MATCH("A-23",Signale!$J$2:$J$150,0))),"") | I24: =IFERROR(IF(INDEX(Signale!$M$2:$M$150,MATCH("A-23",Signale!$J$2:$J$150,0))="","",INDEX(Signale!$M$2:$M$150,MATCH("A-23",Signale!$J$2:$J$150,0))),"")
A25: 24 | B25: =IFERROR(INDEX(Signale!$B$2:$B$150,MATCH("A-24",Signale!$J$2:$J$150,0)),"") | C25: =IFERROR(INDEX(Signale!$A$2:$A$150,MATCH("A-24",Signale!$J$2:$J$150,0)),"") | D25: =IFERROR(INDEX(Signale!$C$2:$C$150,MATCH("A-24",Signale!$J$2:$J$150,0)),"") | E25: =IFERROR(INDEX(Signale!$E$2:$E$150,MATCH("A-24",Signale!$J$2:$J$150,0)),"") | F25: =IFERROR(INDEX(Signale!$F$2:$F$150,MATCH("A-24",Signale!$J$2:$J$150,0)),"") | G25: =IF(COUNTIF(Signale!$J$2:$J$150,"A-24")=0,"frei",IF(COUNTIF(Signale!$J$2:$J$150,"A-24")>1,"DOPPELT","belegt")) | H25: =IFERROR(IF(INDEX(Signale!$L$2:$L$150,MATCH("A-24",Signale!$J$2:$J$150,0))="","",INDEX(Signale!$L$2:$L$150,MATCH("A-24",Signale!$J$2:$J$150,0))),"") | I25: =IFERROR(IF(INDEX(Signale!$M$2:$M$150,MATCH("A-24",Signale!$J$2:$J$150,0))="","",INDEX(Signale!$M$2:$M$150,MATCH("A-24",Signale!$J$2:$J$150,0))),"")
A26: 25 | B26: =IFERROR(INDEX(Signale!$B$2:$B$150,MATCH("A-25",Signale!$J$2:$J$150,0)),"") | C26: =IFERROR(INDEX(Signale!$A$2:$A$150,MATCH("A-25",Signale!$J$2:$J$150,0)),"") | D26: =IFERROR(INDEX(Signale!$C$2:$C$150,MATCH("A-25",Signale!$J$2:$J$150,0)),"") | E26: =IFERROR(INDEX(Signale!$E$2:$E$150,MATCH("A-25",Signale!$J$2:$J$150,0)),"") | F26: =IFERROR(INDEX(Signale!$F$2:$F$150,MATCH("A-25",Signale!$J$2:$J$150,0)),"") | G26: =IF(COUNTIF(Signale!$J$2:$J$150,"A-25")=0,"frei",IF(COUNTIF(Signale!$J$2:$J$150,"A-25")>1,"DOPPELT","belegt")) | H26: =IFERROR(IF(INDEX(Signale!$L$2:$L$150,MATCH("A-25",Signale!$J$2:$J$150,0))="","",INDEX(Signale!$L$2:$L$150,MATCH("A-25",Signale!$J$2:$J$150,0))),"") | I26: =IFERROR(IF(INDEX(Signale!$M$2:$M$150,MATCH("A-25",Signale!$J$2:$J$150,0))="","",INDEX(Signale!$M$2:$M$150,MATCH("A-25",Signale!$J$2:$J$150,0))),"")
A27: 26 | B27: =IFERROR(INDEX(Signale!$B$2:$B$150,MATCH("A-26",Signale!$J$2:$J$150,0)),"") | C27: =IFERROR(INDEX(Signale!$A$2:$A$150,MATCH("A-26",Signale!$J$2:$J$150,0)),"") | D27: =IFERROR(INDEX(Signale!$C$2:$C$150,MATCH("A-26",Signale!$J$2:$J$150,0)),"") | E27: =IFERROR(INDEX(Signale!$E$2:$E$150,MATCH("A-26",Signale!$J$2:$J$150,0)),"") | F27: =IFERROR(INDEX(Signale!$F$2:$F$150,MATCH("A-26",Signale!$J$2:$J$150,0)),"") | G27: =IF(COUNTIF(Signale!$J$2:$J$150,"A-26")=0,"frei",IF(COUNTIF(Signale!$J$2:$J$150,"A-26")>1,"DOPPELT","belegt")) | H27: =IFERROR(IF(INDEX(Signale!$L$2:$L$150,MATCH("A-26",Signale!$J$2:$J$150,0))="","",INDEX(Signale!$L$2:$L$150,MATCH("A-26",Signale!$J$2:$J$150,0))),"") | I27: =IFERROR(IF(INDEX(Signale!$M$2:$M$150,MATCH("A-26",Signale!$J$2:$J$150,0))="","",INDEX(Signale!$M$2:$M$150,MATCH("A-26",Signale!$J$2:$J$150,0))),"")
A28: 27 | B28: =IFERROR(INDEX(Signale!$B$2:$B$150,MATCH("A-27",Signale!$J$2:$J$150,0)),"") | C28: =IFERROR(INDEX(Signale!$A$2:$A$150,MATCH("A-27",Signale!$J$2:$J$150,0)),"") | D28: =IFERROR(INDEX(Signale!$C$2:$C$150,MATCH("A-27",Signale!$J$2:$J$150,0)),"") | E28: =IFERROR(INDEX(Signale!$E$2:$E$150,MATCH("A-27",Signale!$J$2:$J$150,0)),"") | F28: =IFERROR(INDEX(Signale!$F$2:$F$150,MATCH("A-27",Signale!$J$2:$J$150,0)),"") | G28: =IF(COUNTIF(Signale!$J$2:$J$150,"A-27")=0,"frei",IF(COUNTIF(Signale!$J$2:$J$150,"A-27")>1,"DOPPELT","belegt")) | H28: =IFERROR(IF(INDEX(Signale!$L$2:$L$150,MATCH("A-27",Signale!$J$2:$J$150,0))="","",INDEX(Signale!$L$2:$L$150,MATCH("A-27",Signale!$J$2:$J$150,0))),"") | I28: =IFERROR(IF(INDEX(Signale!$M$2:$M$150,MATCH("A-27",Signale!$J$2:$J$150,0))="","",INDEX(Signale!$M$2:$M$150,MATCH("A-27",Signale!$J$2:$J$150,0))),"")
A29: 28 | B29: =IFERROR(INDEX(Signale!$B$2:$B$150,MATCH("A-28",Signale!$J$2:$J$150,0)),"") | C29: =IFERROR(INDEX(Signale!$A$2:$A$150,MATCH("A-28",Signale!$J$2:$J$150,0)),"") | D29: =IFERROR(INDEX(Signale!$C$2:$C$150,MATCH("A-28",Signale!$J$2:$J$150,0)),"") | E29: =IFERROR(INDEX(Signale!$E$2:$E$150,MATCH("A-28",Signale!$J$2:$J$150,0)),"") | F29: =IFERROR(INDEX(Signale!$F$2:$F$150,MATCH("A-28",Signale!$J$2:$J$150,0)),"") | G29: =IF(COUNTIF(Signale!$J$2:$J$150,"A-28")=0,"frei",IF(COUNTIF(Signale!$J$2:$J$150,"A-28")>1,"DOPPELT","belegt")) | H29: =IFERROR(IF(INDEX(Signale!$L$2:$L$150,MATCH("A-28",Signale!$J$2:$J$150,0))="","",INDEX(Signale!$L$2:$L$150,MATCH("A-28",Signale!$J$2:$J$150,0))),"") | I29: =IFERROR(IF(INDEX(Signale!$M$2:$M$150,MATCH("A-28",Signale!$J$2:$J$150,0))="","",INDEX(Signale!$M$2:$M$150,MATCH("A-28",Signale!$J$2:$J$150,0))),"")
A30: 29 | B30: =IFERROR(INDEX(Signale!$B$2:$B$150,MATCH("A-29",Signale!$J$2:$J$150,0)),"") | C30: =IFERROR(INDEX(Signale!$A$2:$A$150,MATCH("A-29",Signale!$J$2:$J$150,0)),"") | D30: =IFERROR(INDEX(Signale!$C$2:$C$150,MATCH("A-29",Signale!$J$2:$J$150,0)),"") | E30: =IFERROR(INDEX(Signale!$E$2:$E$150,MATCH("A-29",Signale!$J$2:$J$150,0)),"") | F30: =IFERROR(INDEX(Signale!$F$2:$F$150,MATCH("A-29",Signale!$J$2:$J$150,0)),"") | G30: =IF(COUNTIF(Signale!$J$2:$J$150,"A-29")=0,"frei",IF(COUNTIF(Signale!$J$2:$J$150,"A-29")>1,"DOPPELT","belegt")) | H30: =IFERROR(IF(INDEX(Signale!$L$2:$L$150,MATCH("A-29",Signale!$J$2:$J$150,0))="","",INDEX(Signale!$L$2:$L$150,MATCH("A-29",Signale!$J$2:$J$150,0))),"") | I30: =IFERROR(IF(INDEX(Signale!$M$2:$M$150,MATCH("A-29",Signale!$J$2:$J$150,0))="","",INDEX(Signale!$M$2:$M$150,MATCH("A-29",Signale!$J$2:$J$150,0))),"")
A31: 30 | B31: =IFERROR(INDEX(Signale!$B$2:$B$150,MATCH("A-30",Signale!$J$2:$J$150,0)),"") | C31: =IFERROR(INDEX(Signale!$A$2:$A$150,MATCH("A-30",Signale!$J$2:$J$150,0)),"") | D31: =IFERROR(INDEX(Signale!$C$2:$C$150,MATCH("A-30",Signale!$J$2:$J$150,0)),"") | E31: =IFERROR(INDEX(Signale!$E$2:$E$150,MATCH("A-30",Signale!$J$2:$J$150,0)),"") | F31: =IFERROR(INDEX(Signale!$F$2:$F$150,MATCH("A-30",Signale!$J$2:$J$150,0)),"") | G31: =IF(COUNTIF(Signale!$J$2:$J$150,"A-30")=0,"frei",IF(COUNTIF(Signale!$J$2:$J$150,"A-30")>1,"DOPPELT","belegt")) | H31: =IFERROR(IF(INDEX(Signale!$L$2:$L$150,MATCH("A-30",Signale!$J$2:$J$150,0))="","",INDEX(Signale!$L$2:$L$150,MATCH("A-30",Signale!$J$2:$J$150,0))),"") | I31: =IFERROR(IF(INDEX(Signale!$M$2:$M$150,MATCH("A-30",Signale!$J$2:$J$150,0))="","",INDEX(Signale!$M$2:$M$150,MATCH("A-30",Signale!$J$2:$J$150,0))),"")
A32: 31 | B32: =IFERROR(INDEX(Signale!$B$2:$B$150,MATCH("A-31",Signale!$J$2:$J$150,0)),"") | C32: =IFERROR(INDEX(Signale!$A$2:$A$150,MATCH("A-31",Signale!$J$2:$J$150,0)),"") | D32: =IFERROR(INDEX(Signale!$C$2:$C$150,MATCH("A-31",Signale!$J$2:$J$150,0)),"") | E32: =IFERROR(INDEX(Signale!$E$2:$E$150,MATCH("A-31",Signale!$J$2:$J$150,0)),"") | F32: =IFERROR(INDEX(Signale!$F$2:$F$150,MATCH("A-31",Signale!$J$2:$J$150,0)),"") | G32: =IF(COUNTIF(Signale!$J$2:$J$150,"A-31")=0,"frei",IF(COUNTIF(Signale!$J$2:$J$150,"A-31")>1,"DOPPELT","belegt")) | H32: =IFERROR(IF(INDEX(Signale!$L$2:$L$150,MATCH("A-31",Signale!$J$2:$J$150,0))="","",INDEX(Signale!$L$2:$L$150,MATCH("A-31",Signale!$J$2:$J$150,0))),"") | I32: =IFERROR(IF(INDEX(Signale!$M$2:$M$150,MATCH("A-31",Signale!$J$2:$J$150,0))="","",INDEX(Signale!$M$2:$M$150,MATCH("A-31",Signale!$J$2:$J$150,0))),"")
A33: 32 | B33: =IFERROR(INDEX(Signale!$B$2:$B$150,MATCH("A-32",Signale!$J$2:$J$150,0)),"") | C33: =IFERROR(INDEX(Signale!$A$2:$A$150,MATCH("A-32",Signale!$J$2:$J$150,0)),"") | D33: =IFERROR(INDEX(Signale!$C$2:$C$150,MATCH("A-32",Signale!$J$2:$J$150,0)),"") | E33: =IFERROR(INDEX(Signale!$E$2:$E$150,MATCH("A-32",Signale!$J$2:$J$150,0)),"") | F33: =IFERROR(INDEX(Signale!$F$2:$F$150,MATCH("A-32",Signale!$J$2:$J$150,0)),"") | G33: =IF(COUNTIF(Signale!$J$2:$J$150,"A-32")=0,"frei",IF(COUNTIF(Signale!$J$2:$J$150,"A-32")>1,"DOPPELT","belegt")) | H33: =IFERROR(IF(INDEX(Signale!$L$2:$L$150,MATCH("A-32",Signale!$J$2:$J$150,0))="","",INDEX(Signale!$L$2:$L$150,MATCH("A-32",Signale!$J$2:$J$150,0))),"") | I33: =IFERROR(IF(INDEX(Signale!$M$2:$M$150,MATCH("A-32",Signale!$J$2:$J$150,0))="","",INDEX(Signale!$M$2:$M$150,MATCH("A-32",Signale!$J$2:$J$150,0))),"")
A34: 33 | B34: =IFERROR(INDEX(Signale!$B$2:$B$150,MATCH("A-33",Signale!$J$2:$J$150,0)),"") | C34: =IFERROR(INDEX(Signale!$A$2:$A$150,MATCH("A-33",Signale!$J$2:$J$150,0)),"") | D34: =IFERROR(INDEX(Signale!$C$2:$C$150,MATCH("A-33",Signale!$J$2:$J$150,0)),"") | E34: =IFERROR(INDEX(Signale!$E$2:$E$150,MATCH("A-33",Signale!$J$2:$J$150,0)),"") | F34: =IFERROR(INDEX(Signale!$F$2:$F$150,MATCH("A-33",Signale!$J$2:$J$150,0)),"") | G34: =IF(COUNTIF(Signale!$J$2:$J$150,"A-33")=0,"frei",IF(COUNTIF(Signale!$J$2:$J$150,"A-33")>1,"DOPPELT","belegt")) | H34: =IFERROR(IF(INDEX(Signale!$L$2:$L$150,MATCH("A-33",Signale!$J$2:$J$150,0))="","",INDEX(Signale!$L$2:$L$150,MATCH("A-33",Signale!$J$2:$J$150,0))),"") | I34: =IFERROR(IF(INDEX(Signale!$M$2:$M$150,MATCH("A-33",Signale!$J$2:$J$150,0))="","",INDEX(Signale!$M$2:$M$150,MATCH("A-33",Signale!$J$2:$J$150,0))),"")
A35: 34 | B35: =IFERROR(INDEX(Signale!$B$2:$B$150,MATCH("A-34",Signale!$J$2:$J$150,0)),"") | C35: =IFERROR(INDEX(Signale!$A$2:$A$150,MATCH("A-34",Signale!$J$2:$J$150,0)),"") | D35: =IFERROR(INDEX(Signale!$C$2:$C$150,MATCH("A-34",Signale!$J$2:$J$150,0)),"") | E35: =IFERROR(INDEX(Signale!$E$2:$E$150,MATCH("A-34",Signale!$J$2:$J$150,0)),"") | F35: =IFERROR(INDEX(Signale!$F$2:$F$150,MATCH("A-34",Signale!$J$2:$J$150,0)),"") | G35: =IF(COUNTIF(Signale!$J$2:$J$150,"A-34")=0,"frei",IF(COUNTIF(Signale!$J$2:$J$150,"A-34")>1,"DOPPELT","belegt")) | H35: =IFERROR(IF(INDEX(Signale!$L$2:$L$150,MATCH("A-34",Signale!$J$2:$J$150,0))="","",INDEX(Signale!$L$2:$L$150,MATCH("A-34",Signale!$J$2:$J$150,0))),"") | I35: =IFERROR(IF(INDEX(Signale!$M$2:$M$150,MATCH("A-34",Signale!$J$2:$J$150,0))="","",INDEX(Signale!$M$2:$M$150,MATCH("A-34",Signale!$J$2:$J$150,0))),"")
A37: Belegt | B37: =COUNTIF(G2:G35,"belegt")+COUNTIF(G2:G35,"DOPPELT")
A38: Frei | B38: =COUNTIF(G2:G35,"frei")

Sheet Stecker B
A1: Pin | B1: Signal | C1: Gruppe | D1: Netz | E1: Typ | F1: Strom max | G1: Belegung | H1: Kabelfarbe | I1: Querschnitt mm²
A2: 1 | B2: =IFERROR(INDEX(Signale!$B$2:$B$150,MATCH("B-1",Signale!$J$2:$J$150,0)),"") | C2: =IFERROR(INDEX(Signale!$A$2:$A$150,MATCH("B-1",Signale!$J$2:$J$150,0)),"") | D2: =IFERROR(INDEX(Signale!$C$2:$C$150,MATCH("B-1",Signale!$J$2:$J$150,0)),"") | E2: =IFERROR(INDEX(Signale!$E$2:$E$150,MATCH("B-1",Signale!$J$2:$J$150,0)),"") | F2: =IFERROR(INDEX(Signale!$F$2:$F$150,MATCH("B-1",Signale!$J$2:$J$150,0)),"") | G2: =IF(COUNTIF(Signale!$J$2:$J$150,"B-1")=0,"frei",IF(COUNTIF(Signale!$J$2:$J$150,"B-1")>1,"DOPPELT","belegt")) | H2: =IFERROR(IF(INDEX(Signale!$L$2:$L$150,MATCH("B-1",Signale!$J$2:$J$150,0))="","",INDEX(Signale!$L$2:$L$150,MATCH("B-1",Signale!$J$2:$J$150,0))),"") | I2: =IFERROR(IF(INDEX(Signale!$M$2:$M$150,MATCH("B-1",Signale!$J$2:$J$150,0))="","",INDEX(Signale!$M$2:$M$150,MATCH("B-1",Signale!$J$2:$J$150,0))),"")
A3: 2 | B3: =IFERROR(INDEX(Signale!$B$2:$B$150,MATCH("B-2",Signale!$J$2:$J$150,0)),"") | C3: =IFERROR(INDEX(Signale!$A$2:$A$150,MATCH("B-2",Signale!$J$2:$J$150,0)),"") | D3: =IFERROR(INDEX(Signale!$C$2:$C$150,MATCH("B-2",Signale!$J$2:$J$150,0)),"") | E3: =IFERROR(INDEX(Signale!$E$2:$E$150,MATCH("B-2",Signale!$J$2:$J$150,0)),"") | F3: =IFERROR(INDEX(Signale!$F$2:$F$150,MATCH("B-2",Signale!$J$2:$J$150,0)),"") | G3: =IF(COUNTIF(Signale!$J$2:$J$150,"B-2")=0,"frei",IF(COUNTIF(Signale!$J$2:$J$150,"B-2")>1,"DOPPELT","belegt")) | H3: =IFERROR(IF(INDEX(Signale!$L$2:$L$150,MATCH("B-2",Signale!$J$2:$J$150,0))="","",INDEX(Signale!$L$2:$L$150,MATCH("B-2",Signale!$J$2:$J$150,0))),"") | I3: =IFERROR(IF(INDEX(Signale!$M$2:$M$150,MATCH("B-2",Signale!$J$2:$J$150,0))="","",INDEX(Signale!$M$2:$M$150,MATCH("B-2",Signale!$J$2:$J$150,0))),"")
A4: 3 | B4: =IFERROR(INDEX(Signale!$B$2:$B$150,MATCH("B-3",Signale!$J$2:$J$150,0)),"") | C4: =IFERROR(INDEX(Signale!$A$2:$A$150,MATCH("B-3",Signale!$J$2:$J$150,0)),"") | D4: =IFERROR(INDEX(Signale!$C$2:$C$150,MATCH("B-3",Signale!$J$2:$J$150,0)),"") | E4: =IFERROR(INDEX(Signale!$E$2:$E$150,MATCH("B-3",Signale!$J$2:$J$150,0)),"") | F4: =IFERROR(INDEX(Signale!$F$2:$F$150,MATCH("B-3",Signale!$J$2:$J$150,0)),"") | G4: =IF(COUNTIF(Signale!$J$2:$J$150,"B-3")=0,"frei",IF(COUNTIF(Signale!$J$2:$J$150,"B-3")>1,"DOPPELT","belegt")) | H4: =IFERROR(IF(INDEX(Signale!$L$2:$L$150,MATCH("B-3",Signale!$J$2:$J$150,0))="","",INDEX(Signale!$L$2:$L$150,MATCH("B-3",Signale!$J$2:$J$150,0))),"") | I4: =IFERROR(IF(INDEX(Signale!$M$2:$M$150,MATCH("B-3",Signale!$J$2:$J$150,0))="","",INDEX(Signale!$M$2:$M$150,MATCH("B-3",Signale!$J$2:$J$150,0))),"")
A5: 4 | B5: =IFERROR(INDEX(Signale!$B$2:$B$150,MATCH("B-4",Signale!$J$2:$J$150,0)),"") | C5: =IFERROR(INDEX(Signale!$A$2:$A$150,MATCH("B-4",Signale!$J$2:$J$150,0)),"") | D5: =IFERROR(INDEX(Signale!$C$2:$C$150,MATCH("B-4",Signale!$J$2:$J$150,0)),"") | E5: =IFERROR(INDEX(Signale!$E$2:$E$150,MATCH("B-4",Signale!$J$2:$J$150,0)),"") | F5: =IFERROR(INDEX(Signale!$F$2:$F$150,MATCH("B-4",Signale!$J$2:$J$150,0)),"") | G5: =IF(COUNTIF(Signale!$J$2:$J$150,"B-4")=0,"frei",IF(COUNTIF(Signale!$J$2:$J$150,"B-4")>1,"DOPPELT","belegt")) | H5: =IFERROR(IF(INDEX(Signale!$L$2:$L$150,MATCH("B-4",Signale!$J$2:$J$150,0))="","",INDEX(Signale!$L$2:$L$150,MATCH("B-4",Signale!$J$2:$J$150,0))),"") | I5: =IFERROR(IF(INDEX(Signale!$M$2:$M$150,MATCH("B-4",Signale!$J$2:$J$150,0))="","",INDEX(Signale!$M$2:$M$150,MATCH("B-4",Signale!$J$2:$J$150,0))),"")
A6: 5 | B6: =IFERROR(INDEX(Signale!$B$2:$B$150,MATCH("B-5",Signale!$J$2:$J$150,0)),"") | C6: =IFERROR(INDEX(Signale!$A$2:$A$150,MATCH("B-5",Signale!$J$2:$J$150,0)),"") | D6: =IFERROR(INDEX(Signale!$C$2:$C$150,MATCH("B-5",Signale!$J$2:$J$150,0)),"") | E6: =IFERROR(INDEX(Signale!$E$2:$E$150,MATCH("B-5",Signale!$J$2:$J$150,0)),"") | F6: =IFERROR(INDEX(Signale!$F$2:$F$150,MATCH("B-5",Signale!$J$2:$J$150,0)),"") | G6: =IF(COUNTIF(Signale!$J$2:$J$150,"B-5")=0,"frei",IF(COUNTIF(Signale!$J$2:$J$150,"B-5")>1,"DOPPELT","belegt")) | H6: =IFERROR(IF(INDEX(Signale!$L$2:$L$150,MATCH("B-5",Signale!$J$2:$J$150,0))="","",INDEX(Signale!$L$2:$L$150,MATCH("B-5",Signale!$J$2:$J$150,0))),"") | I6: =IFERROR(IF(INDEX(Signale!$M$2:$M$150,MATCH("B-5",Signale!$J$2:$J$150,0))="","",INDEX(Signale!$M$2:$M$150,MATCH("B-5",Signale!$J$2:$J$150,0))),"")
A7: 6 | B7: =IFERROR(INDEX(Signale!$B$2:$B$150,MATCH("B-6",Signale!$J$2:$J$150,0)),"") | C7: =IFERROR(INDEX(Signale!$A$2:$A$150,MATCH("B-6",Signale!$J$2:$J$150,0)),"") | D7: =IFERROR(INDEX(Signale!$C$2:$C$150,MATCH("B-6",Signale!$J$2:$J$150,0)),"") | E7: =IFERROR(INDEX(Signale!$E$2:$E$150,MATCH("B-6",Signale!$J$2:$J$150,0)),"") | F7: =IFERROR(INDEX(Signale!$F$2:$F$150,MATCH("B-6",Signale!$J$2:$J$150,0)),"") | G7: =IF(COUNTIF(Signale!$J$2:$J$150,"B-6")=0,"frei",IF(COUNTIF(Signale!$J$2:$J$150,"B-6")>1,"DOPPELT","belegt")) | H7: =IFERROR(IF(INDEX(Signale!$L$2:$L$150,MATCH("B-6",Signale!$J$2:$J$150,0))="","",INDEX(Signale!$L$2:$L$150,MATCH("B-6",Signale!$J$2:$J$150,0))),"") | I7: =IFERROR(IF(INDEX(Signale!$M$2:$M$150,MATCH("B-6",Signale!$J$2:$J$150,0))="","",INDEX(Signale!$M$2:$M$150,MATCH("B-6",Signale!$J$2:$J$150,0))),"")
A8: 7 | B8: =IFERROR(INDEX(Signale!$B$2:$B$150,MATCH("B-7",Signale!$J$2:$J$150,0)),"") | C8: =IFERROR(INDEX(Signale!$A$2:$A$150,MATCH("B-7",Signale!$J$2:$J$150,0)),"") | D8: =IFERROR(INDEX(Signale!$C$2:$C$150,MATCH("B-7",Signale!$J$2:$J$150,0)),"") | E8: =IFERROR(INDEX(Signale!$E$2:$E$150,MATCH("B-7",Signale!$J$2:$J$150,0)),"") | F8: =IFERROR(INDEX(Signale!$F$2:$F$150,MATCH("B-7",Signale!$J$2:$J$150,0)),"") | G8: =IF(COUNTIF(Signale!$J$2:$J$150,"B-7")=0,"frei",IF(COUNTIF(Signale!$J$2:$J$150,"B-7")>1,"DOPPELT","belegt")) | H8: =IFERROR(IF(INDEX(Signale!$L$2:$L$150,MATCH("B-7",Signale!$J$2:$J$150,0))="","",INDEX(Signale!$L$2:$L$150,MATCH("B-7",Signale!$J$2:$J$150,0))),"") | I8: =IFERROR(IF(INDEX(Signale!$M$2:$M$150,MATCH("B-7",Signale!$J$2:$J$150,0))="","",INDEX(Signale!$M$2:$M$150,MATCH("B-7",Signale!$J$2:$J$150,0))),"")
A9: 8 | B9: =IFERROR(INDEX(Signale!$B$2:$B$150,MATCH("B-8",Signale!$J$2:$J$150,0)),"") | C9: =IFERROR(INDEX(Signale!$A$2:$A$150,MATCH("B-8",Signale!$J$2:$J$150,0)),"") | D9: =IFERROR(INDEX(Signale!$C$2:$C$150,MATCH("B-8",Signale!$J$2:$J$150,0)),"") | E9: =IFERROR(INDEX(Signale!$E$2:$E$150,MATCH("B-8",Signale!$J$2:$J$150,0)),"") | F9: =IFERROR(INDEX(Signale!$F$2:$F$150,MATCH("B-8",Signale!$J$2:$J$150,0)),"") | G9: =IF(COUNTIF(Signale!$J$2:$J$150,"B-8")=0,"frei",IF(COUNTIF(Signale!$J$2:$J$150,"B-8")>1,"DOPPELT","belegt")) | H9: =IFERROR(IF(INDEX(Signale!$L$2:$L$150,MATCH("B-8",Signale!$J$2:$J$150,0))="","",INDEX(Signale!$L$2:$L$150,MATCH("B-8",Signale!$J$2:$J$150,0))),"") | I9: =IFERROR(IF(INDEX(Signale!$M$2:$M$150,MATCH("B-8",Signale!$J$2:$J$150,0))="","",INDEX(Signale!$M$2:$M$150,MATCH("B-8",Signale!$J$2:$J$150,0))),"")
A10: 9 | B10: =IFERROR(INDEX(Signale!$B$2:$B$150,MATCH("B-9",Signale!$J$2:$J$150,0)),"") | C10: =IFERROR(INDEX(Signale!$A$2:$A$150,MATCH("B-9",Signale!$J$2:$J$150,0)),"") | D10: =IFERROR(INDEX(Signale!$C$2:$C$150,MATCH("B-9",Signale!$J$2:$J$150,0)),"") | E10: =IFERROR(INDEX(Signale!$E$2:$E$150,MATCH("B-9",Signale!$J$2:$J$150,0)),"") | F10: =IFERROR(INDEX(Signale!$F$2:$F$150,MATCH("B-9",Signale!$J$2:$J$150,0)),"") | G10: =IF(COUNTIF(Signale!$J$2:$J$150,"B-9")=0,"frei",IF(COUNTIF(Signale!$J$2:$J$150,"B-9")>1,"DOPPELT","belegt")) | H10: =IFERROR(IF(INDEX(Signale!$L$2:$L$150,MATCH("B-9",Signale!$J$2:$J$150,0))="","",INDEX(Signale!$L$2:$L$150,MATCH("B-9",Signale!$J$2:$J$150,0))),"") | I10: =IFERROR(IF(INDEX(Signale!$M$2:$M$150,MATCH("B-9",Signale!$J$2:$J$150,0))="","",INDEX(Signale!$M$2:$M$150,MATCH("B-9",Signale!$J$2:$J$150,0))),"")
A11: 10 | B11: =IFERROR(INDEX(Signale!$B$2:$B$150,MATCH("B-10",Signale!$J$2:$J$150,0)),"") | C11: =IFERROR(INDEX(Signale!$A$2:$A$150,MATCH("B-10",Signale!$J$2:$J$150,0)),"") | D11: =IFERROR(INDEX(Signale!$C$2:$C$150,MATCH("B-10",Signale!$J$2:$J$150,0)),"") | E11: =IFERROR(INDEX(Signale!$E$2:$E$150,MATCH("B-10",Signale!$J$2:$J$150,0)),"") | F11: =IFERROR(INDEX(Signale!$F$2:$F$150,MATCH("B-10",Signale!$J$2:$J$150,0)),"") | G11: =IF(COUNTIF(Signale!$J$2:$J$150,"B-10")=0,"frei",IF(COUNTIF(Signale!$J$2:$J$150,"B-10")>1,"DOPPELT","belegt")) | H11: =IFERROR(IF(INDEX(Signale!$L$2:$L$150,MATCH("B-10",Signale!$J$2:$J$150,0))="","",INDEX(Signale!$L$2:$L$150,MATCH("B-10",Signale!$J$2:$J$150,0))),"") | I11: =IFERROR(IF(INDEX(Signale!$M$2:$M$150,MATCH("B-10",Signale!$J$2:$J$150,0))="","",INDEX(Signale!$M$2:$M$150,MATCH("B-10",Signale!$J$2:$J$150,0))),"")
A12: 11 | B12: =IFERROR(INDEX(Signale!$B$2:$B$150,MATCH("B-11",Signale!$J$2:$J$150,0)),"") | C12: =IFERROR(INDEX(Signale!$A$2:$A$150,MATCH("B-11",Signale!$J$2:$J$150,0)),"") | D12: =IFERROR(INDEX(Signale!$C$2:$C$150,MATCH("B-11",Signale!$J$2:$J$150,0)),"") | E12: =IFERROR(INDEX(Signale!$E$2:$E$150,MATCH("B-11",Signale!$J$2:$J$150,0)),"") | F12: =IFERROR(INDEX(Signale!$F$2:$F$150,MATCH("B-11",Signale!$J$2:$J$150,0)),"") | G12: =IF(COUNTIF(Signale!$J$2:$J$150,"B-11")=0,"frei",IF(COUNTIF(Signale!$J$2:$J$150,"B-11")>1,"DOPPELT","belegt")) | H12: =IFERROR(IF(INDEX(Signale!$L$2:$L$150,MATCH("B-11",Signale!$J$2:$J$150,0))="","",INDEX(Signale!$L$2:$L$150,MATCH("B-11",Signale!$J$2:$J$150,0))),"") | I12: =IFERROR(IF(INDEX(Signale!$M$2:$M$150,MATCH("B-11",Signale!$J$2:$J$150,0))="","",INDEX(Signale!$M$2:$M$150,MATCH("B-11",Signale!$J$2:$J$150,0))),"")
